2019-05-10 12:32:31,407 [Thread-2:123145484849152] [django.request:228] [log:log_response] [WARNING]- Forbidden: /api/module/user/zhangyadan
2019-05-10 12:34:10,779 [Thread-3:123145484849152] [django.request:228] [log:log_response] [WARNING]- Forbidden: /api/module/user/undefined
2019-05-10 12:34:46,296 [Thread-4:123145484849152] [django.request:228] [log:log_response] [WARNING]- Forbidden: /api/module/user/undefined
2019-05-10 12:36:06,013 [Thread-5:123145484849152] [django.request:228] [log:log_response] [WARNING]- Forbidden: /api/module/user/undefined
2019-05-10 13:48:50,951 [Thread-8:123145484849152] [django.request:228] [log:log_response] [WARNING]- Forbidden: /api/module/user/zhangyadan
2019-05-10 14:22:27,101 [Thread-44:123145484849152] [django.request:228] [log:log_response] [WARNING]- Forbidden: /api/module/user/zhangyadan
2019-05-10 14:53:22,160 [Thread-90:123145484849152] [django.request:228] [log:log_response] [WARNING]- Forbidden: /api/module/user/zhangyadan
2019-05-10 15:48:10,877 [Thread-2:123145440010240] [django.request:228] [log:log_response] [WARNING]- Forbidden: /api/getTestScripts/2
2019-05-10 16:17:44,692 [Thread-2:123145391226880] [django.request:228] [log:log_response] [WARNING]- Forbidden: /api/testScripts/1
2019-05-10 16:21:38,977 [Thread-2:123145538285568] [django.request:228] [log:log_response] [ERROR]- Internal Server Error: /api/testScripts/1
Traceback (most recent call last):
  File "/Users/liuzhanhui/workspace/python/web_auto/venv/lib/python3.6/site-packages/django/core/handlers/exception.py", line 34, in inner
    response = get_response(request)
  File "/Users/liuzhanhui/workspace/python/web_auto/venv/lib/python3.6/site-packages/django/core/handlers/base.py", line 115, in _get_response
    response = self.process_exception_by_middleware(e, request)
  File "/Users/liuzhanhui/workspace/python/web_auto/venv/lib/python3.6/site-packages/django/core/handlers/base.py", line 113, in _get_response
    response = wrapped_callback(request, *callback_args, **callback_kwargs)
  File "/Users/liuzhanhui/workspace/python/web_auto/venv/lib/python3.6/site-packages/django/views/decorators/csrf.py", line 54, in wrapped_view
    return view_func(*args, **kwargs)
  File "/Users/liuzhanhui/workspace/python/web_auto/venv/lib/python3.6/site-packages/django/views/generic/base.py", line 71, in view
    return self.dispatch(request, *args, **kwargs)
  File "/Users/liuzhanhui/workspace/python/web_auto/venv/lib/python3.6/site-packages/rest_framework/views.py", line 497, in dispatch
    self.response = self.finalize_response(request, response, *args, **kwargs)
  File "/Users/liuzhanhui/workspace/python/web_auto/venv/lib/python3.6/site-packages/rest_framework/views.py", line 412, in finalize_response
    % type(response)
AssertionError: Expected a `Response`, `HttpResponse` or `HttpStreamingResponse` to be returned from the view, but received a `<class 'NoneType'>`
2019-05-10 16:22:22,253 [Thread-2:123145538285568] [django.request:228] [log:log_response] [ERROR]- Internal Server Error: /api/testScripts/1
Traceback (most recent call last):
  File "/Users/liuzhanhui/workspace/python/web_auto/venv/lib/python3.6/site-packages/django/core/handlers/exception.py", line 34, in inner
    response = get_response(request)
  File "/Users/liuzhanhui/workspace/python/web_auto/venv/lib/python3.6/site-packages/django/core/handlers/base.py", line 115, in _get_response
    response = self.process_exception_by_middleware(e, request)
  File "/Users/liuzhanhui/workspace/python/web_auto/venv/lib/python3.6/site-packages/django/core/handlers/base.py", line 113, in _get_response
    response = wrapped_callback(request, *callback_args, **callback_kwargs)
  File "/Users/liuzhanhui/workspace/python/web_auto/venv/lib/python3.6/site-packages/django/views/decorators/csrf.py", line 54, in wrapped_view
    return view_func(*args, **kwargs)
  File "/Users/liuzhanhui/workspace/python/web_auto/venv/lib/python3.6/site-packages/django/views/generic/base.py", line 71, in view
    return self.dispatch(request, *args, **kwargs)
  File "/Users/liuzhanhui/workspace/python/web_auto/venv/lib/python3.6/site-packages/rest_framework/views.py", line 497, in dispatch
    self.response = self.finalize_response(request, response, *args, **kwargs)
  File "/Users/liuzhanhui/workspace/python/web_auto/venv/lib/python3.6/site-packages/rest_framework/views.py", line 412, in finalize_response
    % type(response)
AssertionError: Expected a `Response`, `HttpResponse` or `HttpStreamingResponse` to be returned from the view, but received a `<class 'NoneType'>`
2019-05-10 16:22:31,066 [Thread-2:123145538285568] [django.request:228] [log:log_response] [WARNING]- Not Found: /api/testScripts/1/
2019-05-10 16:22:37,331 [Thread-2:123145538285568] [django.request:228] [log:log_response] [ERROR]- Internal Server Error: /api/testScripts/1
Traceback (most recent call last):
  File "/Users/liuzhanhui/workspace/python/web_auto/venv/lib/python3.6/site-packages/django/core/handlers/exception.py", line 34, in inner
    response = get_response(request)
  File "/Users/liuzhanhui/workspace/python/web_auto/venv/lib/python3.6/site-packages/django/core/handlers/base.py", line 115, in _get_response
    response = self.process_exception_by_middleware(e, request)
  File "/Users/liuzhanhui/workspace/python/web_auto/venv/lib/python3.6/site-packages/django/core/handlers/base.py", line 113, in _get_response
    response = wrapped_callback(request, *callback_args, **callback_kwargs)
  File "/Users/liuzhanhui/workspace/python/web_auto/venv/lib/python3.6/site-packages/django/views/decorators/csrf.py", line 54, in wrapped_view
    return view_func(*args, **kwargs)
  File "/Users/liuzhanhui/workspace/python/web_auto/venv/lib/python3.6/site-packages/django/views/generic/base.py", line 71, in view
    return self.dispatch(request, *args, **kwargs)
  File "/Users/liuzhanhui/workspace/python/web_auto/venv/lib/python3.6/site-packages/rest_framework/views.py", line 497, in dispatch
    self.response = self.finalize_response(request, response, *args, **kwargs)
  File "/Users/liuzhanhui/workspace/python/web_auto/venv/lib/python3.6/site-packages/rest_framework/views.py", line 412, in finalize_response
    % type(response)
AssertionError: Expected a `Response`, `HttpResponse` or `HttpStreamingResponse` to be returned from the view, but received a `<class 'NoneType'>`
2019-05-10 16:25:18,070 [Thread-2:123145503498240] [django.request:228] [log:log_response] [WARNING]- Not Found: /api/testScripts/2
2019-05-10 16:32:07,646 [Thread-2:123145404719104] [django.request:228] [log:log_response] [WARNING]- Not Found: /api/testScripts/mo/2
2019-05-10 16:58:50,859 [Thread-2:123145441845248] [django.request:228] [log:log_response] [WARNING]- Forbidden: /api/module/user/zhangyadan
2019-05-10 17:53:31,873 [Thread-85:123145441845248] [django.request:228] [log:log_response] [WARNING]- Forbidden: /api/module/user/zhangyadan
2019-05-10 18:27:28,538 [Thread-93:123145441845248] [django.request:228] [log:log_response] [WARNING]- Forbidden: /api/module/user/zhangyadan
2019-05-10 18:40:31,038 [Thread-110:123145441845248] [django.request:228] [log:log_response] [WARNING]- Forbidden: /api/module/user/zhangyadan
